Workbook

Sheet Monthly
C1: aggregate number | D1: 0 | E1: 1 | F1: 2 | G1: 3 | H1: 4 | I1: 5 | J1: 6 | K1: 7 | L1: 8 | M1: 9 | N1: 10 | O1: 11 | P1: 12 | Q1: 4.1 | R1: 4.5
C2: cdid | D2: L522 | E2: L523 | F2: L524 | G2: L525 | H2: L5PG | I2: L527 | J2: L528 | K2: L529 | L2: L52A | M2: L52B | N2: L52C | O2: L52D | P2: L52E | Q2: L536 | R2: L53D
A3: index date | C3: name | D3: CPIH ALL ITEMS | E3: FOOD AND NON-ALCOHOLIC BEVERAGES | F3: ALCOHOLIC BEVERAGES AND TOBACCO | G3: CLOTHING AND FOOTWEAR | H3: HOUSING, WATER, ELELCTRICITY, GAS AND OTHER FUELS | I3: FURNITURE, HOUSEHOLD EQUIPMENT AND MAINTENANCE | J3: HEALTH | K3: TRANSPORT | L3: COMMUNICATION | M3: RECREATION & CULTURE | N3: EDUCATION | O3: RESTAURANTS AND HOTELS | P3: MISCELLANEOUS GOODS AND SERVICES | Q3: ACTUAL RENTALS FOR HOUSING | R3: ELECTRICITY, GAS AND OTHER FUELS
A4: 198801 | B4: =IF(MOD(A4,100)>=4, INT(A4/100), INT(A4/100)-1) -> 1987 | C4: 32143 | D4: 46.851 | E4: 47.901 | F4: 27.262 | G4: 191.973 | H4: 38.714 | I4: 68.285 | J4: 37.606 | K4: 40.338 | L4: 96.974 | M4: 73.343 | N4: 12.344 | O4: 32.871 | P4: 45.903 | Q4: 31.135 | R4: 29.131
A5: 198802 | B5: =IF(MOD(A5,100)>=4, INT(A5/100), INT(A5/100)-1) -> 1987 | C5: 32174 | D5: 46.998 | E5: 48.174 | F5: 27.365 | G5: 193.181 | H5: 38.791 | I5: 68.649 | J5: 37.662 | K5: 40.317 | L5: 96.963 | M5: 73.553 | N5: 12.348 | O5: 33.025 | P5: 46.086 | Q5: 31.16 | R5: 29.077
A6: 198803 | B6: =IF(MOD(A6,100)>=4, INT(A6/100), INT(A6/100)-1) -> 1987 | C6: 32203 | D6: 47.202 | E6: 48.324 | F6: 27.433 | G6: 194.76 | H6: 38.993 | I6: 69.179 | J6: 38.192 | K6: 40.559 | L6: 96.968 | M6: 73.58 | N6: 12.349 | O6: 33.115 | P6: 46.108 | Q6: 31.183 | R6: 29.029
A7: 198804 | B7: =IF(MOD(A7,100)>=4, INT(A7/100), INT(A7/100)-1) -> 1988 | C7: 32234 | D7: 47.801 | E7: 48.592 | F7: 27.824 | G7: 195.128 | H7: 39.763 | I7: 69.502 | J7: 38.385 | K7: 41.075 | L7: 96.966 | M7: 74.924 | N7: 12.36 | O7: 33.526 | P7: 46.369 | Q7: 32.915 | R7: 29.387
A8: 198805 | B8: =IF(MOD(A8,100)>=4, INT(A8/100), INT(A8/100)-1) -> 1988 | C8: 32264 | D8: 48.044 | E8: 48.714 | F8: 27.931 | G8: 197.851 | H8: 40.011 | I8: 69.834 | J8: 38.513 | K8: 41.217 | L8: 96.958 | M8: 75.22 | N8: 12.365 | O8: 33.67 | P8: 46.538 | Q8: 32.975 | R8: 29.819
A9: 198806 | B9: =IF(MOD(A9,100)>=4, INT(A9/100), INT(A9/100)-1) -> 1988 | C9: 32295 | D9: 48.21 | E9: 48.793 | F9: 27.942 | G9: 198.489 | H9: 40.179 | I9: 69.987 | J9: 38.608 | K9: 41.582 | L9: 96.948 | M9: 75.162 | N9: 12.377 | O9: 33.785 | P9: 46.703 | Q9: 33.136 | R9: 30.338
A10: 198807 | B10: =IF(MOD(A10,100)>=4, INT(A10/100), INT(A10/100)-1) -> 1988 | C10: 32325 | D10: 48.233 | E10: 48.355 | F10: 27.941 | G10: 195.092 | H10: 40.351 | I10: 69.9 | J10: 38.683 | K10: 41.829 | L10: 96.938 | M10: 75.262 | N10: 12.375 | O10: 33.887 | P10: 47.195 | Q10: 33.238 | R10: 30.67
A11: 198808 | B11: =IF(MOD(A11,100)>=4, INT(A11/100), INT(A11/100)-1) -> 1988 | C11: 32356 | D11: 48.491 | E11: 48.583 | F11: 27.968 | G11: 195.298 | H11: 40.694 | I11: 70.211 | J11: 38.919 | K11: 41.995 | L11: 96.921 | M11: 75.439 | N11: 12.392 | O11: 34.116 | P11: 47.408 | Q11: 33.221 | R11: 30.617
A12: 198809 | B12: =IF(MOD(A12,100)>=4, INT(A12/100), INT(A12/100)-1) -> 1988 | C12: 32387 | D12: 48.716 | E12: 48.765 | F12: 28.016 | G12: 198.023 | H12: 40.83 | I12: 70.752 | J12: 39.014 | K12: 42.107 | L12: 97.645 | M12: 75.386 | N12: 13.117 | O12: 34.359 | P12: 47.56 | Q12: 33.294 | R12: 30.708
A13: 198810 | B13: =IF(MOD(A13,100)>=4, INT(A13/100), INT(A13/100)-1) -> 1988 | C13: 32417 | D13: 49.045 | E13: 48.838 | F13: 28.115 | G13: 201.946 | H13: 41.28 | I13: 70.942 | J13: 39.269 | K13: 42.203 | L13: 97.621 | M13: 75.67 | N13: 13.126 | O13: 34.555 | P13: 47.719 | Q13: 33.587 | R13: 30.744
A14: 198811 | B14: =IF(MOD(A14,100)>=4, INT(A14/100), INT(A14/100)-1) -> 1988 | C14: 32448 | D14: 49.307 | E14: 49.205 | F14: 28.146 | G14: 203.159 | H14: 41.616 | I14: 71.256 | J14: 39.468 | K14: 42.184 | L14: 97.625 | M14: 75.814 | N14: 13.168 | O14: 34.715 | P14: 48.13 | Q14: 33.669 | R14: 30.783
A15: 198812 | B15: =IF(MOD(A15,100)>=4, INT(A15/100), INT(A15/100)-1) -> 1988 | C15: 32478 | D15: 49.337 | E15: 49.545 | F15: 28.062 | G15: 203.868 | H15: 41.555 | I15: 71.303 | J15: 39.488 | K15: 42.075 | L15: 97.627 | M15: 75.863 | N15: 13.17 | O15: 34.794 | P15: 48.237 | Q15: 33.545 | R15: 30.843
... A207: 200412 | B207: =IF(MOD(A207,100)>=4, INT(A207/100), INT(A207/100)-1) -> 2004 | C207: 38322 | D207: 78.622 | E207: 70.765 | F207: 61.433 | G207: 126.205 | H207: 76.169 | I207: 85.149 | J207: 74.223 | K207: 73.162 | L207: 87.631 | M207: 99.036 | N207: 39.863 | O207: 72.692 | P207: 81.039 | Q207: 75.466 | R207: 45.069
A208: 200501 | B208: =IF(MOD(A208,100)>=4, INT(A208/100), INT(A208/100)-1) -> 2004 | C208: 38353 | D208: 78.321 | E208: 70.907 | F208: 62.055 | G208: 121.641 | H208: 76.358 | I208: 81.776 | J208: 74.741 | K208: 72.015 | L208: 87.526 | M208: 98.505 | N208: 39.863 | O208: 72.779 | P208: 81.932 | Q208: 75.687 | R208: 45.778
A209: 200502 | B209: =IF(MOD(A209,100)>=4, INT(A209/100), INT(A209/100)-1) -> 2004 | C209: 38384 | D209: 78.497 | E209: 71.411 | F209: 62.338 | G209: 121.495 | H209: 76.462 | I209: 82.103 | J209: 74.86 | K209: 72.693 | L209: 87.709 | M209: 98.038 | N209: 39.863 | O209: 72.975 | P209: 81.977 | Q209: 75.724 | R209: 46.048
A210: 200503 | B210: =IF(MOD(A210,100)>=4, INT(A210/100), INT(A210/100)-1) -> 2004 | C210: 38412 | D210: 78.801 | E210: 71.999 | F210: 62.034 | G210: 122.406 | H210: 76.662 | I210: 83.448 | J210: 74.92 | K210: 73.237 | L210: 87.586 | M210: 98.069 | N210: 39.863 | O210: 73.17 | P210: 82.142 | Q210: 75.72 | R210: 46.526
A211: 200504 | B211: =IF(MOD(A211,100)>=4, INT(A211/100), INT(A211/100)-1) -> 2005 | C211: 38443 | D211: 79.13 | E211: 71.35 | F211: 62.761 | G211: 121.979 | H211: 77.388 | I211: 82.352 | J211: 75.362 | K211: 73.647 | L211: 87.592 | M211: 98.479 | N211: 39.863 | O211: 73.758 | P211: 82.551 | Q211: 77.092 | R211: 46.78
A212: 200505 | B212: =IF(MOD(A212,100)>=4, INT(A212/100), INT(A212/100)-1) -> 2005 | C212: 38473 | D212: 79.355 | E212: 71.803 | F212: 63.009 | G212: 122.024 | H212: 77.52 | I212: 83.019 | J212: 75.507 | K212: 74.333 | L212: 87.208 | M212: 98.237 | N212: 39.863 | O212: 73.991 | P212: 82.671 | Q212: 77.157 | R212: 46.762
A213: 200506 | B213: =IF(MOD(A213,100)>=4, INT(A213/100), INT(A213/100)-1) -> 2005 | C213: 38504 | D213: 79.426 | E213: 71.82 | F213: 63.03 | G213: 121.627 | H213: 77.679 | I213: 83.253 | J213: 75.581 | K213: 74.41 | L213: 87.398 | M213: 98.072 | N213: 39.863 | O213: 74.086 | P213: 82.797 | Q213: 77.16 | R213: 47.09
A214: 200507 | B214: =IF(MOD(A214,100)>=4, INT(A214/100), INT(A214/100)-1) -> 2005 | C214: 38534 | D214: 79.478 | E214: 71.01 | F214: 63.175 | G214: 116.724 | H214: 77.851 | I214: 82.496 | J214: 76.189 | K214: 76.129 | L214: 86.686 | M214: 97.611 | N214: 39.863 | O214: 74.339 | P214: 83.525 | Q214: 77.628 | R214: 47.31
A215: 200508 | B215: =IF(MOD(A215,100)>=4, INT(A215/100), INT(A215/100)-1) -> 2005 | C215: 38565 | D215: 79.713 | E215: 71.155 | F215: 63.124 | G215: 118.723 | H215: 77.966 | I215: 82.599 | J215: 76.345 | K215: 77.035 | L215: 87.022 | M215: 97.158 | N215: 39.863 | O215: 74.577 | P215: 83.672 | Q215: 77.742 | R215: 47.579
A216: 200509 | B216: =IF(MOD(A216,100)>=4, INT(A216/100), INT(A216/100)-1) -> 2005 | C216: 38596 | D216: 79.857 | E216: 71.171 | F216: 63.028 | G216: 120.71 | H216: 78.154 | I216: 83.14 | J216: 76.279 | K216: 76.363 | L216: 86.933 | M216: 97.447 | N216: 40.71 | O216: 74.772 | P216: 83.83 | Q216: 77.815 | R216: 48.187
A217: 200510 | B217: =IF(MOD(A217,100)>=4, INT(A217/100), INT(A217/100)-1) -> 2005 | C217: 38626 | D217: 79.997 | E217: 71.008 | F217: 63.296 | G217: 120.736 | H217: 78.496 | I217: 82.494 | J217: 76.484 | K217: 76.181 | L217: 86.708 | M217: 97.517 | N217: 41.75 | O217: 75.007 | P217: 84.198 | Q217: 77.853 | R217: 49.622
A218: 200511 | B218: =IF(MOD(A218,100)>=4, INT(A218/100), INT(A218/100)-1) -> 2005 | C218: 38657 | D218: 80.017 | E218: 71.463 | F218: 63.318 | G218: 121.431 | H218: 78.673 | I218: 83.33 | J218: 76.461 | K218: 75.035 | L218: 86.747 | M218: 97.322 | N218: 41.75 | O218: 75.056 | P218: 84.375 | Q218: 77.901 | R218: 50.561
A219: 200512 | B219: =IF(MOD(A219,100)>=4, INT(A219/100), INT(A219/100)-1) -> 2005 | C219: 38687 | D219: 80.259 | E219: 71.912 | F219: 63.028 | G219: 120.978 | H219: 78.953 | I219: 85.207 | J219: 75.978 | K219: 75.287 | L219: 86.62 | M219: 97.372 | N219: 41.75 | O219: 75.215 | P219: 84.443 | Q219: 77.972 | R219: 51.335
... A291: 201112 | B291: =IF(MOD(A291,100)>=4, INT(A291/100), INT(A291/100)-1) -> 2011 | C291: 40878 | D291: 95.03 | E291: 98.131 | F291: 83.626 | G291: 99.635 | H291: 93.791 | I291: 98.802 | J291: 91.494 | K291: 99.885 | L291: 92.916 | M291: 98.377 | N291: 68.012 | O291: 91.581 | P291: 97.887 | Q291: 90.704 | R291: 93.962
A292: 201201 | B292: =IF(MOD(A292,100)>=4, INT(A292/100), INT(A292/100)-1) -> 2011 | C292: 40909 | D292: 94.677 | E292: 97.795 | F292: 85.202 | G292: 94.827 | H292: 93.947 | I292: 96.568 | J292: 92.157 | K292: 99.231 | L292: 92.645 | M292: 98.333 | N292: 68.012 | O292: 91.566 | P292: 97.797 | Q292: 91.003 | R292: 93.972
A293: 201202 | B293: =IF(MOD(A293,100)>=4, INT(A293/100), INT(A293/100)-1) -> 2011 | C293: 40940 | D293: 95.157 | E293: 98.973 | F293: 85.903 | G293: 97.511 | H293: 93.897 | I293: 98.073 | J293: 92.263 | K293: 99.835 | L293: 93.171 | M293: 98.23 | N293: 68.012 | O293: 91.916 | P293: 98.392 | Q293: 91.002 | R293: 93.119
A294: 201203 | B294: =IF(MOD(A294,100)>=4, INT(A294/100), INT(A294/100)-1) -> 2011 | C294: 40969 | D294: 95.411 | E294: 98.503 | F294: 86.057 | G294: 99.58 | H294: 93.91 | I294: 99.399 | J294: 92.243 | K294: 100.568 | L294: 93.685 | M294: 98.151 | N294: 68.012 | O294: 92.123 | P294: 98.372 | Q294: 91.077 | R294: 92.59
A295: 201204 | B295: =IF(MOD(A295,100)>=4, INT(A295/100), INT(A295/100)-1) -> 2012 | C295: 41000 | D295: 95.897 | E295: 98.378 | F295: 88.596 | G295: 99.772 | H295: 94.324 | I295: 98.16 | J295: 93.264 | K295: 101.772 | L295: 94.093 | M295: 98.58 | N295: 68.012 | O295: 93.024 | P295: 98.53 | Q295: 92.432 | R295: 92.214
A296: 201205 | B296: =IF(MOD(A296,100)>=4, INT(A296/100), INT(A296/100)-1) -> 2012 | C296: 41030 | D296: 95.875 | E296: 98.708 | F296: 88.53 | G296: 99.651 | H296: 94.353 | I296: 98.83 | J296: 93.221 | K296: 100.983 | L296: 95.055 | M296: 98.159 | N296: 68.012 | O296: 93.417 | P296: 98.558 | Q296: 92.536 | R296: 91.908
A297: 201206 | B297: =IF(MOD(A297,100)>=4, INT(A297/100), INT(A297/100)-1) -> 2012 | C297: 41061 | D297: 95.581 | E297: 98.603 | F297: 88.065 | G297: 95.489 | H297: 94.395 | I297: 98.851 | J297: 93.623 | K297: 100.475 | L297: 94.898 | M297: 98.258 | N297: 68.012 | O297: 93.462 | P297: 98.309 | Q297: 92.531 | R297: 91.572
A298: 201207 | B298: =IF(MOD(A298,100)>=4, INT(A298/100), INT(A298/100)-1) -> 2012 | C298: 41091 | D298: 95.665 | E298: 98.775 | F298: 88.713 | G298: 93.014 | H298: 94.586 | I298: 97.796 | J298: 93.603 | K298: 101.432 | L298: 95.24 | M298: 98.387 | N298: 68.012 | O298: 93.657 | P298: 98.416 | Q298: 93.307 | R298: 91.667
A299: 201208 | B299: =IF(MOD(A299,100)>=4, INT(A299/100), INT(A299/100)-1) -> 2012 | C299: 41122 | D299: 96.081 | E299: 98.985 | F299: 88.908 | G299: 95.64 | H299: 94.734 | I299: 98.586 | J299: 93.62 | K299: 102.731 | L299: 95.312 | M299: 98.155 | N299: 68.012 | O299: 93.755 | P299: 98.683 | Q299: 93.401 | R299: 91.943
A300: 201209 | B300: =IF(MOD(A300,100)>=4, INT(A300/100), INT(A300/100)-1) -> 2012 | C300: 41153 | D300: 96.418 | E300: 98.981 | F300: 89.849 | G300: 100.075 | H300: 94.875 | I300: 99.095 | J300: 93.769 | K300: 101.484 | L300: 95.3 | M300: 98.815 | N300: 68.341 | O300: 94.02 | P300: 99.346 | Q300: 93.414 | R300: 92.066
A301: 201210 | B301: =IF(MOD(A301,100)>=4, INT(A301/100), INT(A301/100)-1) -> 2012 | C301: 41183 | D301: 96.831 | E301: 99.474 | F301: 90.188 | G301: 101.258 | H301: 94.948 | I301: 98.525 | J301: 93.907 | K301: 101.362 | L301: 95.485 | M301: 99.181 | N301: 81.426 | O301: 93.982 | P301: 99.357 | Q301: 93.807 | R301: 91.986
A302: 201211 | B302: =IF(MOD(A302,100)>=4, INT(A302/100), INT(A302/100)-1) -> 2012 | C302: 41214 | D302: 96.972 | E302: 100.559 | F302: 89.735 | G302: 101.89 | H302: 95.234 | I302: 98.439 | J302: 93.954 | K302: 100.376 | L302: 95.287 | M302: 99.112 | N302: 81.426 | O302: 94.499 | P302: 99.724 | Q302: 93.893 | R302: 93.465
...

Sheet Financial Year Averages
A1: Financial Year | B1: All Items | C1: Food | D1: Alcohol | E1: Clothing | F1: Housing | G1: Furniture | H1: Health | I1: Transport | J1: Communication | K1: Recreation | L1: Education | M1: Restaurants | N1: Misc | O1: Actual Rent
A2: 2015 | B2: =AVERAGEIF(Monthly!$B$4:$B$461,$A2,Monthly!D$4:D$461) -> 100.1655 | C2: =AVERAGEIF(Monthly!$B$4:$B$461,$A2,Monthly!E$4:E$461) -> 99.359833 | D2: =AVERAGEIF(Monthly!$B$4:$B$461,$A2,Monthly!F$4:F$461) -> 100.27842 | E2: =AVERAGEIF(Monthly!$B$4:$B$461,$A2,Monthly!G$4:G$461) -> 100.17075 | F2: =AVERAGEIF(Monthly!$B$4:$B$461,$A2,Monthly!H$4:H$461) -> 100.34033 | G2: =AVERAGEIF(Monthly!$B$4:$B$461,$A2,Monthly!I$4:I$461) -> 100.0585 | H2: =AVERAGEIF(Monthly!$B$4:$B$461,$A2,Monthly!J$4:J$461) -> 100.51175 | I2: =AVERAGEIF(Monthly!$B$4:$B$461,$A2,Monthly!K$4:K$461) -> 99.871417 | ... O2: =AVERAGEIF(Monthly!$B$4:$B$461,$A2,Monthly!Q$4:Q$461) -> 100.72233
A3: 2016 | B3: =AVERAGEIF(Monthly!$B$4:$B$461,$A3,Monthly!D$4:D$461) -> 101.53617 | C3: =AVERAGEIF(Monthly!$B$4:$B$461,$A3,Monthly!E$4:E$461) -> 97.686833 | D3: =AVERAGEIF(Monthly!$B$4:$B$461,$A3,Monthly!F$4:F$461) -> 102.32092 | E3: =AVERAGEIF(Monthly!$B$4:$B$461,$A3,Monthly!G$4:G$461) -> 100.24567 | F3: =AVERAGEIF(Monthly!$B$4:$B$461,$A3,Monthly!H$4:H$461) -> 102.13883 | G3: =AVERAGEIF(Monthly!$B$4:$B$461,$A3,Monthly!I$4:I$461) -> 100.109 | H3: =AVERAGEIF(Monthly!$B$4:$B$461,$A3,Monthly!J$4:J$461) -> 102.70283 | I3: =AVERAGEIF(Monthly!$B$4:$B$461,$A3,Monthly!K$4:K$461) -> 101.86 | ... O3: =AVERAGEIF(Monthly!$B$4:$B$461,$A3,Monthly!Q$4:Q$461) -> 102.063
A4: 2017 | B4: =AVERAGEIF(Monthly!$B$4:$B$461,$A4,Monthly!D$4:D$461) -> 104.22325 | C4: =AVERAGEIF(Monthly!$B$4:$B$461,$A4,Monthly!E$4:E$461) -> 100.62633 | D4: =AVERAGEIF(Monthly!$B$4:$B$461,$A4,Monthly!F$4:F$461) -> 107.18333 | E4: =AVERAGEIF(Monthly!$B$4:$B$461,$A4,Monthly!G$4:G$461) -> 103.45533 | F4: =AVERAGEIF(Monthly!$B$4:$B$461,$A4,Monthly!H$4:H$461) -> 104.18933 | G4: =AVERAGEIF(Monthly!$B$4:$B$461,$A4,Monthly!I$4:I$461) -> 103.22658 | H4: =AVERAGEIF(Monthly!$B$4:$B$461,$A4,Monthly!J$4:J$461) -> 105.429 | I4: =AVERAGEIF(Monthly!$B$4:$B$461,$A4,Monthly!K$4:K$461) -> 105.66108 | ... O4: =AVERAGEIF(Monthly!$B$4:$B$461,$A4,Monthly!Q$4:Q$461) -> 102.80433
A5: 2018 | B5: =AVERAGEIF(Monthly!$B$4:$B$461,$A5,Monthly!D$4:D$461) -> 106.4275 | C5: =AVERAGEIF(Monthly!$B$4:$B$461,$A5,Monthly!E$4:E$461) -> 102.1525 | D5: =AVERAGEIF(Monthly!$B$4:$B$461,$A5,Monthly!F$4:F$461) -> 111.809 | E5: =AVERAGEIF(Monthly!$B$4:$B$461,$A5,Monthly!G$4:G$461) -> 103.06717 | F5: =AVERAGEIF(Monthly!$B$4:$B$461,$A5,Monthly!H$4:H$461) -> 106.02292 | G5: =AVERAGEIF(Monthly!$B$4:$B$461,$A5,Monthly!I$4:I$461) -> 104.29217 | H5: =AVERAGEIF(Monthly!$B$4:$B$461,$A5,Monthly!J$4:J$461) -> 107.94308 | I5: =AVERAGEIF(Monthly!$B$4:$B$461,$A5,Monthly!K$4:K$461) -> 110.24417 | ... O5: =AVERAGEIF(Monthly!$B$4:$B$461,$A5,Monthly!Q$4:Q$461) -> 103.36333
A6: 2019 | B6: =AVERAGEIF(Monthly!$B$4:$B$461,$A6,Monthly!D$4:D$461) -> 108.24917 | C6: =AVERAGEIF(Monthly!$B$4:$B$461,$A6,Monthly!E$4:E$461) -> 103.64933 | D6: =AVERAGEIF(Monthly!$B$4:$B$461,$A6,Monthly!F$4:F$461) -> 114.71592 | E6: =AVERAGEIF(Monthly!$B$4:$B$461,$A6,Monthly!G$4:G$461) -> 102.52392 | F6: =AVERAGEIF(Monthly!$B$4:$B$461,$A6,Monthly!H$4:H$461) -> 107.88217 | G6: =AVERAGEIF(Monthly!$B$4:$B$461,$A6,Monthly!I$4:I$461) -> 105.14792 | H6: =AVERAGEIF(Monthly!$B$4:$B$461,$A6,Monthly!J$4:J$461) -> 110.89258 | I6: =AVERAGEIF(Monthly!$B$4:$B$461,$A6,Monthly!K$4:K$461) -> 112.05733 | ... O6: =AVERAGEIF(Monthly!$B$4:$B$461,$A6,Monthly!Q$4:Q$461) -> 104.14392
A7: 2020 | B7: =AVERAGEIF(Monthly!$B$4:$B$461,$A7,Monthly!D$4:D$461) -> 109.12025 | C7: =AVERAGEIF(Monthly!$B$4:$B$461,$A7,Monthly!E$4:E$461) -> 103.80775 | D7: =AVERAGEIF(Monthly!$B$4:$B$461,$A7,Monthly!F$4:F$461) -> 117.58825 | E7: =AVERAGEIF(Monthly!$B$4:$B$461,$A7,Monthly!G$4:G$461) -> 100.093 | F7: =AVERAGEIF(Monthly!$B$4:$B$461,$A7,Monthly!H$4:H$461) -> 108.55033 | G7: =AVERAGEIF(Monthly!$B$4:$B$461,$A7,Monthly!I$4:I$461) -> 105.38983 | H7: =AVERAGEIF(Monthly!$B$4:$B$461,$A7,Monthly!J$4:J$461) -> 112.74475 | I7: =AVERAGEIF(Monthly!$B$4:$B$461,$A7,Monthly!K$4:K$461) -> 112.85742 | ... O7: =AVERAGEIF(Monthly!$B$4:$B$461,$A7,Monthly!Q$4:Q$461) -> 105.88483
A8: 2021 | B8: =AVERAGEIF(Monthly!$B$4:$B$461,$A8,Monthly!D$4:D$461) -> 113.12967 | C8: =AVERAGEIF(Monthly!$B$4:$B$461,$A8,Monthly!E$4:E$461) -> 105.66408 | D8: =AVERAGEIF(Monthly!$B$4:$B$461,$A8,Monthly!F$4:F$461) -> 121.0975 | E8: =AVERAGEIF(Monthly!$B$4:$B$461,$A8,Monthly!G$4:G$461) -> 103.44717 | F8: =AVERAGEIF(Monthly!$B$4:$B$461,$A8,Monthly!H$4:H$461) -> 111.82508 | G8: =AVERAGEIF(Monthly!$B$4:$B$461,$A8,Monthly!I$4:I$461) -> 111.33217 | H8: =AVERAGEIF(Monthly!$B$4:$B$461,$A8,Monthly!J$4:J$461) -> 114.81333 | I8: =AVERAGEIF(Monthly!$B$4:$B$461,$A8,Monthly!K$4:K$461) -> 123.69483 | ... O8: =AVERAGEIF(Monthly!$B$4:$B$461,$A8,Monthly!Q$4:Q$461) -> 107.80975
A9: 2022 | B9: =AVERAGEIF(Monthly!$B$4:$B$461,$A9,Monthly!D$4:D$461) -> 123.044 | C9: =AVERAGEIF(Monthly!$B$4:$B$461,$A9,Monthly!E$4:E$461) -> 120.66683 | D9: =AVERAGEIF(Monthly!$B$4:$B$461,$A9,Monthly!F$4:F$461) -> 127.25467 | E9: =AVERAGEIF(Monthly!$B$4:$B$461,$A9,Monthly!G$4:G$461) -> 111.0115 | F9: =AVERAGEIF(Monthly!$B$4:$B$461,$A9,Monthly!H$4:H$461) -> 123.41558 | G9: =AVERAGEIF(Monthly!$B$4:$B$461,$A9,Monthly!I$4:I$461) -> 122.45842 | H9: =AVERAGEIF(Monthly!$B$4:$B$461,$A9,Monthly!J$4:J$461) -> 119.34825 | I9: =AVERAGEIF(Monthly!$B$4:$B$461,$A9,Monthly!K$4:K$461) -> 135.10225 | ... O9: =AVERAGEIF(Monthly!$B$4:$B$461,$A9,Monthly!Q$4:Q$461) -> 112.18417
A10: 2023 | B10: =AVERAGEIF(Monthly!$B$4:$B$461,$A10,Monthly!D$4:D$461) -> 129.87942 | C10: =AVERAGEIF(Monthly!$B$4:$B$461,$A10,Monthly!E$4:E$461) -> 134.33117 | D10: =AVERAGEIF(Monthly!$B$4:$B$461,$A10,Monthly!F$4:F$461) -> 140.86642 | E10: =AVERAGEIF(Monthly!$B$4:$B$461,$A10,Monthly!G$4:G$461) -> 117.85725 | F10: =AVERAGEIF(Monthly!$B$4:$B$461,$A10,Monthly!H$4:H$461) -> 128.80408 | G10: =AVERAGEIF(Monthly!$B$4:$B$461,$A10,Monthly!I$4:I$461) -> 126.90808 | H10: =AVERAGEIF(Monthly!$B$4:$B$461,$A10,Monthly!J$4:J$461) -> 128.66025 | I10: =AVERAGEIF(Monthly!$B$4:$B$461,$A10,Monthly!K$4:K$461) -> 134.63233 | ... O10: =AVERAGEIF(Monthly!$B$4:$B$461,$A10,Monthly!Q$4:Q$461) -> 119.24367
VB22: =AVERAGEIF(Monthly!$B$4:$B$461,$A2,Monthly!D$4:D$461) -> 100.1655

Sheet Financial Year Inflation
A1: Financial Year | B1: All Items | C1: Food | D1: Alcohol | E1: Clothing | F1: Housing | G1: Furniture | H1: Health | I1: Transport | J1: Communication | K1: Recreation | L1: Education | M1: Restaurants | N1: Misc | O1: Actual Rent
A2: 2015 | B2: =('Financial Year Averages'!B3-'Financial Year Averages'!B2)/'Financial Year Averages'!B2*100 -> 1.368402 | C2: =('Financial Year Averages'!C3-'Financial Year Averages'!C2)/'Financial Year Averages'!C2*100 -> -1.683779 | D2: =('Financial Year Averages'!D3-'Financial Year Averages'!D2)/'Financial Year Averages'!D2*100 -> 2.0368291 | E2: =('Financial Year Averages'!E3-'Financial Year Averages'!E2)/'Financial Year Averages'!E2*100 -> 0.074788965 | F2: =('Financial Year Averages'!F3-'Financial Year Averages'!F2)/'Financial Year Averages'!F2*100 -> 1.7923999 | G2: =('Financial Year Averages'!G3-'Financial Year Averages'!G2)/'Financial Year Averages'!G2*100 -> 0.050470475 | H2: =('Financial Year Averages'!H3-'Financial Year Averages'!H2)/'Financial Year Averages'!H2*100 -> 2.1799276 | I2: =('Financial Year Averages'!I3-'Financial Year Averages'!I2)/'Financial Year Averages'!I2*100 -> 1.9911436 | ... O2: =('Financial Year Averages'!O3-'Financial Year Averages'!O2)/'Financial Year Averages'!O2*100 -> 1.331052
A3: 2016 | B3: =('Financial Year Averages'!B4-'Financial Year Averages'!B3)/'Financial Year Averages'!B3*100 -> 2.6464298 | C3: =('Financial Year Averages'!C4-'Financial Year Averages'!C3)/'Financial Year Averages'!C3*100 -> 3.0091056 | D3: =('Financial Year Averages'!D4-'Financial Year Averages'!D3)/'Financial Year Averages'!D3*100 -> 4.7521238 | E3: =('Financial Year Averages'!E4-'Financial Year Averages'!E3)/'Financial Year Averages'!E3*100 -> 3.2018009 | F3: =('Financial Year Averages'!F4-'Financial Year Averages'!F3)/'Financial Year Averages'!F3*100 -> 2.0075616 | G3: =('Financial Year Averages'!G4-'Financial Year Averages'!G3)/'Financial Year Averages'!G3*100 -> 3.1141889 | H3: =('Financial Year Averages'!H4-'Financial Year Averages'!H3)/'Financial Year Averages'!H3*100 -> 2.6544221 | I3: =('Financial Year Averages'!I4-'Financial Year Averages'!I3)/'Financial Year Averages'!I3*100 -> 3.7316742 | ... O3: =('Financial Year Averages'!O4-'Financial Year Averages'!O3)/'Financial Year Averages'!O3*100 -> 0.72634876
A4: 2017 | B4: =('Financial Year Averages'!B5-'Financial Year Averages'!B4)/'Financial Year Averages'!B4*100 -> 2.1149312 | C4: =('Financial Year Averages'!C5-'Financial Year Averages'!C4)/'Financial Year Averages'!C4*100 -> 1.5166673 | D4: =('Financial Year Averages'!D5-'Financial Year Averages'!D4)/'Financial Year Averages'!D4*100 -> 4.3156585 | E4: =('Financial Year Averages'!E5-'Financial Year Averages'!E4)/'Financial Year Averages'!E4*100 -> -0.37520218 | F4: =('Financial Year Averages'!F5-'Financial Year Averages'!F4)/'Financial Year Averages'!F4*100 -> 1.7598571 | G4: =('Financial Year Averages'!G5-'Financial Year Averages'!G4)/'Financial Year Averages'!G4*100 -> 1.0322761 | H4: =('Financial Year Averages'!H5-'Financial Year Averages'!H4)/'Financial Year Averages'!H4*100 -> 2.3846222 | I4: =('Financial Year Averages'!I5-'Financial Year Averages'!I4)/'Financial Year Averages'!I4*100 -> 4.337532 | ... O4: =('Financial Year Averages'!O5-'Financial Year Averages'!O4)/'Financial Year Averages'!O4*100 -> 0.5437514
A5: 2018 | B5: =('Financial Year Averages'!B6-'Financial Year Averages'!B5)/'Financial Year Averages'!B5*100 -> 1.7116503 | C5: =('Financial Year Averages'!C6-'Financial Year Averages'!C5)/'Financial Year Averages'!C5*100 -> 1.4652929 | D5: =('Financial Year Averages'!D6-'Financial Year Averages'!D5)/'Financial Year Averages'!D5*100 -> 2.5998951 | E5: =('Financial Year Averages'!E6-'Financial Year Averages'!E5)/'Financial Year Averages'!E5*100 -> -0.52708347 | F5: =('Financial Year Averages'!F6-'Financial Year Averages'!F5)/'Financial Year Averages'!F5*100 -> 1.7536303 | G5: =('Financial Year Averages'!G6-'Financial Year Averages'!G5)/'Financial Year Averages'!G5*100 -> 0.82053142 | H5: =('Financial Year Averages'!H6-'Financial Year Averages'!H5)/'Financial Year Averages'!H5*100 -> 2.7324585 | I5: =('Financial Year Averages'!I6-'Financial Year Averages'!I5)/'Financial Year Averages'!I5*100 -> 1.6446826 | ... O5: =('Financial Year Averages'!O6-'Financial Year Averages'!O5)/'Financial Year Averages'!O5*100 -> 0.75518398
A6: 2019 | B6: =('Financial Year Averages'!B7-'Financial Year Averages'!B6)/'Financial Year Averages'!B6*100 -> 0.80470211 | C6: =('Financial Year Averages'!C7-'Financial Year Averages'!C6)/'Financial Year Averages'!C6*100 -> 0.15283906 | D6: =('Financial Year Averages'!D7-'Financial Year Averages'!D6)/'Financial Year Averages'!D6*100 -> 2.5038664 | E6: =('Financial Year Averages'!E7-'Financial Year Averages'!E6)/'Financial Year Averages'!E6*100 -> -2.3710728 | F6: =('Financial Year Averages'!F7-'Financial Year Averages'!F6)/'Financial Year Averages'!F6*100 -> 0.61934858 | G6: =('Financial Year Averages'!G7-'Financial Year Averages'!G6)/'Financial Year Averages'!G6*100 -> 0.23007272 | H6: =('Financial Year Averages'!H7-'Financial Year Averages'!H6)/'Financial Year Averages'!H6*100 -> 1.6702349 | I6: =('Financial Year Averages'!I7-'Financial Year Averages'!I6)/'Financial Year Averages'!I6*100 -> 0.71399462 | ... O6: =('Financial Year Averages'!O7-'Financial Year Averages'!O6)/'Financial Year Averages'!O6*100 -> 1.6716451
A7: 2020 | B7: =('Financial Year Averages'!B8-'Financial Year Averages'!B7)/'Financial Year Averages'!B7*100 -> 3.6743104 | C7: =('Financial Year Averages'!C8-'Financial Year Averages'!C7)/'Financial Year Averages'!C7*100 -> 1.7882416 | D7: =('Financial Year Averages'!D8-'Financial Year Averages'!D7)/'Financial Year Averages'!D7*100 -> 2.9843543 | E7: =('Financial Year Averages'!E8-'Financial Year Averages'!E7)/'Financial Year Averages'!E7*100 -> 3.3510502 | F7: =('Financial Year Averages'!F8-'Financial Year Averages'!F7)/'Financial Year Averages'!F7*100 -> 3.0168033 | G7: =('Financial Year Averages'!G8-'Financial Year Averages'!G7)/'Financial Year Averages'!G7*100 -> 5.6384313 | H7: =('Financial Year Averages'!H8-'Financial Year Averages'!H7)/'Financial Year Averages'!H7*100 -> 1.8347491 | I7: =('Financial Year Averages'!I8-'Financial Year Averages'!I7)/'Financial Year Averages'!I7*100 -> 9.602751 | ... O7: =('Financial Year Averages'!O8-'Financial Year Averages'!O7)/'Financial Year Averages'!O7*100 -> 1.8179343
A8: 2021 | B8: =('Financial Year Averages'!B9-'Financial Year Averages'!B8)/'Financial Year Averages'!B8*100 -> 8.76369 | C8: =('Financial Year Averages'!C9-'Financial Year Averages'!C8)/'Financial Year Averages'!C8*100 -> 14.198533 | D8: =('Financial Year Averages'!D9-'Financial Year Averages'!D8)/'Financial Year Averages'!D8*100 -> 5.0844705 | E8: =('Financial Year Averages'!E9-'Financial Year Averages'!E8)/'Financial Year Averages'!E8*100 -> 7.3122673 | F8: =('Financial Year Averages'!F9-'Financial Year Averages'!F8)/'Financial Year Averages'!F8*100 -> 10.364848 | G8: =('Financial Year Averages'!G9-'Financial Year Averages'!G8)/'Financial Year Averages'!G8*100 -> 9.9937424 | H8: =('Financial Year Averages'!H9-'Financial Year Averages'!H8)/'Financial Year Averages'!H8*100 -> 3.9498171 | I8: =('Financial Year Averages'!I9-'Financial Year Averages'!I8)/'Financial Year Averages'!I8*100 -> 9.2222257 | ... O8: =('Financial Year Averages'!O9-'Financial Year Averages'!O8)/'Financial Year Averages'!O8*100 -> 4.0575334
A9: 2022 | B9: =('Financial Year Averages'!B10-'Financial Year Averages'!B9)/'Financial Year Averages'!B9*100 -> 5.5552621 | C9: =('Financial Year Averages'!C10-'Financial Year Averages'!C9)/'Financial Year Averages'!C9*100 -> 11.324018 | D9: =('Financial Year Averages'!D10-'Financial Year Averages'!D9)/'Financial Year Averages'!D9*100 -> 10.696464 | E9: =('Financial Year Averages'!E10-'Financial Year Averages'!E9)/'Financial Year Averages'!E9*100 -> 6.1667034 | F9: =('Financial Year Averages'!F10-'Financial Year Averages'!F9)/'Financial Year Averages'!F9*100 -> 4.3661423 | G9: =('Financial Year Averages'!G10-'Financial Year Averages'!G9)/'Financial Year Averages'!G9*100 -> 3.6336144 | H9: =('Financial Year Averages'!H10-'Financial Year Averages'!H9)/'Financial Year Averages'!H9*100 -> 7.8023767 | I9: =('Financial Year Averages'!I10-'Financial Year Averages'!I9)/'Financial Year Averages'!I9*100 -> -0.34782298 | ... O9: =('Financial Year Averages'!O10-'Financial Year Averages'!O9)/'Financial Year Averages'!O9*100 -> 6.2927775
A10: 2023 | B10: =('Financial Year Averages'!B11-'Financial Year Averages'!B10)/'Financial Year Averages'!B10*100 -> -100 | C10: =('Financial Year Averages'!C11-'Financial Year Averages'!C10)/'Financial Year Averages'!C10*100 -> -100 | D10: =('Financial Year Averages'!D11-'Financial Year Averages'!D10)/'Financial Year Averages'!D10*100 -> -100 | E10: =('Financial Year Averages'!E11-'Financial Year Averages'!E10)/'Financial Year Averages'!E10*100 -> -100 | F10: =('Financial Year Averages'!F11-'Financial Year Averages'!F10)/'Financial Year Averages'!F10*100 -> -100 | G10: =('Financial Year Averages'!G11-'Financial Year Averages'!G10)/'Financial Year Averages'!G10*100 -> -100 | H10: =('Financial Year Averages'!H11-'Financial Year Averages'!H10)/'Financial Year Averages'!H10*100 -> -100 | I10: =('Financial Year Averages'!I11-'Financial Year Averages'!I10)/'Financial Year Averages'!I10*100 -> -100 | ... O10: =('Financial Year Averages'!O11-'Financial Year Averages'!O10)/'Financial Year Averages'!O10*100 -> -100
